<?xml version="1.0"?>
<robot xmlns:xacro="http://wiki.ros.org/xacro">

	<xacro:include filename="$(find rbares_description)/urdf/" />

	<xacro:property name="PI" value="3.1415926535897931"/>

  <xacro:macro name="solid_cuboid_inertia" params="m h d w">
    <inertia  ixx="${(m*(h*h+d*d))/12}" ixy = "0" ixz = "0"
              iyy="${(m*(w*w+d*d))/12}" iyz = "0"
              izz="${(m*(w*w+h*h))/12}" />
  </xacro:macro>

	<!--xacro:property name="" value=""/-->

  <xacro:macro name="mimetic_base_link" params="prefix parent *origin">

    <!-- The sense of this xacro is to create a link that changes its position mimic to the elevator (on x axis) -->
    <joint name="${prefix}" type="prismatic">
       <xacro:insert_block name="origin" />
       <parent link="${parent}"/>
       <child link="${prefix}_mimetic_base_link" />
     </joint>

    <link name="${prefix}_mimetic_base_link">
       <inertial>
         <mass value="0.0001" />
         <origin xyz="0 0 0" rpy="0 0 0"/>
				 <solid_cuboid_inertia m="0.0001" h="0.01" d="0.01" w="0.01"/>
       </inertial>
     </link>

  </xacro:macro>
</robot>
